<?xml version="1.0" encoding="utf-8"?>
<robot xmlns:xacro="http://www.ros.org/wiki/xacro" name="hand">
  <xacro:macro name="hand" params="connected_to:='' ns:='' rpy:='0 0 0' xyz:='0 0 0' ">
    <xacro:unless value="${connected_to == ''}">
      <joint name="${ns}_hand_joint" type="fixed">
        <parent link="${connected_to}"/>
        <child link="${ns}_hand"/>
        <origin xyz="${xyz}" rpy="${rpy}"/>
      </joint>
    </xacro:unless>

    <xacro:arg name="gazebo" default="true"/>
    <xacro:if value="$(arg gazebo)">
      <!-- Gazebo Tags -->
      <xacro:include filename="$(find franka_gazebo)/robots/hand.gazebo.xacro"/>
    </xacro:if>

    <link name="${ns}_hand">
      <visual>
        <origin rpy="0 0 0" xyz="0 0 0"/>
        <geometry>
          <mesh filename="package://franka_gazebo/meshes/hand.STL"/>
        </geometry>
        <material name="">
          <color rgba="1 1 1 1"/>
        </material>
      </visual>
      <collision>
        <origin rpy="0 0 0" xyz="0 0 0"/>
        <geometry>
          <mesh filename="package://franka_gazebo/meshes/hand_collision.STL"/>
        </geometry>
      </collision>
      <inertial>
        <mass value="0.3"/>
        <origin rpy="0 0 0" xyz="0 0 0"/>
        <inertia
          ixx="0.0001" ixy="0.0" ixz="0.0"
          iyy="0.0001" iyz="0.0"
          izz="0.0001"/>
      </inertial>
    </link>

    <link name="${ns}_leftfinger">
      <visual>
        <origin rpy="0 0 0" xyz="0 0 0"/>
        <geometry>
          <mesh filename="package://franka_gazebo/meshes/leftfinger.STL"/>
        </geometry>
        <material name="">
          <color rgba="1 1 1 1"/>
        </material>
      </visual>
      <collision>
        <geometry>
          <mesh filename="package://franka_gazebo/meshes/leftfinger_collision.STL"/>
        </geometry>
      </collision>
      <inertial>
        <mass value="0.1"/>
        <origin rpy="0 0 0" xyz="0 0 0"/>
        <inertia
          ixx="0.0001" ixy="0.0" ixz="0.0"
          iyy="0.0001" iyz="0.0"
          izz="0.0001"/>
      </inertial>
    </link>

    <link name="${ns}_rightfinger">
      <visual>
        <origin rpy="0 0 0" xyz="0 0 0"/>
        <geometry>
          <mesh filename="package://franka_gazebo/meshes/rightfinger.STL"/>
        </geometry>
        <material name="">
          <color rgba="1 1 1 1"/>
        </material>
      </visual>
      <collision>
        <geometry>
          <mesh filename="package://franka_gazebo/meshes/rightfinger_collision.STL"/>
        </geometry>
      </collision>
      <inertial>
        <mass value="0.1"/>
        <origin rpy="0 0 0" xyz="0 0 0"/>
        <inertia
          ixx="0.0001" ixy="0.0" ixz="0.0"
          iyy="0.0001" iyz="0.0"
          izz="0.0001"/>
      </inertial>
    </link>

    <joint name="${ns}_finger_joint1" type="prismatic">
      <parent link="${ns}_hand"/>
      <child link="${ns}_leftfinger"/>
      <origin xyz="0 0 0.0584" rpy="0 0 0"/>
      <axis xyz="0 1 0"/>
      <limit effort="20" lower="-0.001" upper="0.04" velocity="0.3"/>
    </joint>

    <joint name="${ns}_finger_joint2" type="prismatic">
      <parent link="${ns}_hand"/>
      <child link="${ns}_rightfinger"/>
      <origin xyz="0 0 0.0584" rpy="0 0 0"/>
      <axis xyz="0 -1 0"/>
      <limit effort="20" lower="-0.001" upper="0.04" velocity="0.3"/>
    </joint>

  </xacro:macro>
</robot>
